weight=2
dimensionsToSpawnIn=overworld
embed_into_distance=1
acceptable_target_blocks=stone,grass,dirt,sand,gravel
unacceptable_target_blocks=flowing_water,water,flowing_lava,lava,ice,packed_ice,stained_hardened_clay-9,brick_block,double_stone_slab,stonebrick,red_sandstone,red_nether_brick,red_mushroom_block,brown_mushroom_block,planks,cobblestone,end_stone,obsidian,purpur_block,iron_bars,purpur_slab,purpur_pillar,netherrack,soul_sand,quartz_ore
dimensions=9,7,7
allowable_overhang=2
max_leveling=2
leveling_buffer=-1
preserve_water=0
preserve_lava=0
preserve_plants=0

rule1=0,100,preserveBlock,cobblestone,stone_slab-3
rule2=0,100,brick_block
rule3=1,80,brick_block
rule4=1,50,brick_block
rule5=2,50,brick_block
rule6=0,100,preserveBlock

layer
6,6,2,2,2,6,6
6,2,1,1,1,2,6
2,1,1,1,1,1,2
2,1,1,1,1,1,2
2,1,1,1,1,1,2
6,2,1,1,1,2,6
6,6,2,2,2,6,6
endlayer

layer
0,0,3,3,3,0,0
0,3,0,0,0,3,0
3,0,0,0,0,0,3
3,0,0,0,0,0,3
3,0,0,0,0,0,3
0,3,0,0,0,3,0
0,0,3,3,3,0,0
endlayer

layer
0,0,3,3,3,0,0
0,3,0,0,0,3,0
3,0,0,0,0,0,3
3,0,0,0,0,0,3
3,0,0,0,0,0,3
0,3,0,0,0,3,0
0,0,3,3,3,0,0
endlayer

layer
0,0,3,3,3,0,0
0,3,0,0,0,3,0
3,0,0,0,0,0,3
3,0,0,0,0,0,3
3,0,0,0,0,0,3
0,3,0,0,0,3,0
0,0,3,3,3,0,0
endlayer

layer
0,0,3,3,3,0,0
0,3,5,5,5,3,0
3,5,5,5,5,5,3
3,5,5,5,5,5,3
3,5,5,5,5,5,3
0,3,5,5,5,3,0
0,0,3,3,3,0,0
endlayer

layer
0,0,4,4,4,0,0
0,4,0,0,0,4,0
4,0,0,0,0,0,4
4,0,0,0,0,0,4
4,0,0,0,0,0,4
0,4,0,0,0,4,0
0,0,4,4,4,0,0
endlayer

layer
0,0,4,4,4,0,0
0,4,0,0,0,4,0
4,0,0,0,0,0,4
4,0,0,0,0,0,4
4,0,0,0,0,0,4
0,4,0,0,0,4,0
0,0,4,4,4,0,0
endlayer

layer
0,0,4,4,4,0,0
0,4,0,0,0,4,0
4,0,0,0,0,0,4
4,0,0,0,0,0,4
4,0,0,0,0,0,4
0,4,0,0,0,4,0
0,0,4,4,4,0,0
endlayer

layer
0,0,4,4,4,0,0
0,4,5,5,5,4,0
4,5,5,5,5,5,4
4,5,5,5,5,5,4
4,5,5,5,5,5,4
0,3,5,5,5,4,0
0,0,4,4,4,0,0
endlayer
