weight=15
dimensionsToSpawnIn=overworld
embed_into_distance=34
random_height_offset=0,0
unacceptable_target_blocks=flowing_water,water,flowing_lava,lava,ice,packed_ice
dimensions=34,26,20
allowable_overhang=0
max_leveling=3
leveling_buffer=-1
preventRotation=0
preserve_water=0
preserve_lava=0
uniqueMinDistance=5000
spawnMinDistance=0
spawnMaxDistance=0

adjoining_template=generic/SolarPanel;0;100;0;40

rule1=0,100,preserveBlock
rule2=0,100,minecraft:monster_egg-0,monster_egg-2,monster_egg-2,monster_egg-2,monster_egg-3,stonebrick-2,stonebrick-1,stonebrick-0,stonebrick-0,stonebrick-0,stonebrick-2,stonebrick-1,stonebrick-0,stonebrick-0,stonebrick-0
rule3=0,100,minecraft:redstone_lamp-0
rule4=0,100,ChestGenHook:chests/nether_bridge:9-5
rule5=0,100,MobSpawner:Silverfish,air
rule6=0,100,air
rule7=0,100,minecraft:stained_glass_pane-15
rule8=0,100,ChestGenHook:gameplay/fishing/junk:9-2,ChestGenHook:chests/igloo_chest:1-3,ChestGenHook:chests/spawn_bonus_chest:1-4,ChestGenHook:chests/simple_dungeon:1-5,MediumChest
rule9=0,100,minecraft:stone_brick_stairs-0
rule10=0,100,minecraft:stone_brick_stairs-2
rule11=0,100,minecraft:grass-0
rule12=0,100,minecraft:stone_brick_stairs-3
rule13=0,100,MobSpawner:Skeleton
rule14=0,100,ChestGenHook:gameplay/fishing/junk:9-2,ChestGenHook:chests/woodland_mansion:1-3,ChestGenHook:chests/spawn_bonus_chest:1-4,ChestGenHook:chests/simple_dungeon:1-5,MediumChest
rule15=0,100,minecraft:stone_brick_stairs-1
rule16=0,100,ChestGenHook:gameplay/fishing/junk:9-2,ChestGenHook:chests/woodland_mansion:1-3,ChestGenHook:chests/spawn_bonus_chest:1-4,ChestGenHook:chests/simple_dungeon:1-5,MediumChest
rule17=0,100,minecraft:iron_bars-0
rule18=0,100,minecraft:ladder-4
rule19=0,100,minecraft:tallgrass-1,tallgrass-1,tallgrass-1,tallgrass-1,red_flower-1,red_flower-3,red_flower-6,red_flower-7,red_flower-4
rule20=0,100,MobSpawner:Zombie
rule21=0,100,MobSpawner:Skeleton
rule22=0,100,minecraft:stone_brick_stairs-5
rule23=0,100,minecraft:stone_brick_stairs-7
rule24=0,100,minecraft:stone_brick_stairs-6
rule25=0,100,minecraft:stone_brick_stairs-4
rule26=0,100,minecraft:trapdoor-13
rule27=0,100,minecraft:trapdoor-12
rule28=0,100,minecraft:trapdoor-15
rule29=0,100,minecraft:planks-0
rule30=0,100,minecraft:crafting_table-0
rule31=0,100,minecraft:bed-0
rule32=0,100,minecraft:bed-8
rule33=0,100,minecraft:bookshelf-0
rule34=0,100,minecraft:furnace-2
rule35=0,100,minecraft:dark_oak_door-1
rule36=0,100,ChestGenHook:gameplay/fishing/junk:9-2,ChestGenHook:chests/igloo_chest:1-3,ChestGenHook:chests/spawn_bonus_chest:1-4,ChestGenHook:chests/simple_dungeon:1-5,MediumChest
rule37=0,100,minecraft:dark_oak_door-3
rule38=0,100,minecraft:furnace-3
rule39=0,100,minecraft:bed-10
rule40=0,100,minecraft:bed-2
rule41=0,100,minecraft:vine-1
rule42=0,100,minecraft:vine-8
rule43=0,100,minecraft:vine-9
rule44=0,100,minecraft:leaves-4
rule45=0,100,minecraft:vine-12
rule46=0,100,minecraft:dark_oak_door-8
rule47=0,100,minecraft:vine-4
rule48=0,100,minecraft:vine-15
rule49=0,100,minecraft:leaves-12
rule50=0,100,minecraft:vine-14
rule51=0,100,minecraft:monster_egg-4,monster_egg-2,monster_egg-1,monster_egg-1,monster_egg-3,stonebrick-1,stonebrick-1,stonebrick-0,stonebrick-0,stonebrick-0,preserveBlock,preserveBlock,preserveBlock,preserveBlock,preserveBlock,preserveBlock,preserveBlock,preserveBlock,preserveBlock,preserveBlock,preserveBlock
rule52=0,100,minecraft:flower_pot-0

layer
1,1,1,1,1,1,1,1,1,1,1,1,1,1,1,1,1,1,1,1
1,1,1,1,1,1,1,1,1,1,1,1,1,1,1,1,1,1,1,1
1,1,1,1,1,1,1,1,1,1,1,1,1,1,1,1,1,1,1,1
1,1,1,1,1,1,1,1,1,1,1,1,1,1,1,1,1,1,1,1
1,1,1,1,1,1,1,1,1,1,1,1,1,1,1,1,1,1,1,1
1,1,1,1,1,1,1,1,1,2,2,1,1,1,1,1,1,1,1,1
1,1,1,1,1,1,1,1,1,2,2,1,1,1,1,1,1,1,1,1
1,1,1,1,1,1,1,1,1,2,2,1,1,1,1,1,1,1,1,1
1,1,1,1,1,1,2,2,2,2,2,2,2,2,1,1,1,1,1,1
1,1,1,1,1,2,3,2,2,2,2,2,2,3,2,1,1,1,1,1
1,1,1,1,1,2,2,2,2,2,2,2,2,2,2,1,1,1,1,1
1,1,2,2,2,2,2,2,2,2,2,2,2,2,2,2,2,2,1,1
1,1,2,2,2,2,2,2,2,2,2,2,2,2,2,2,2,2,1,1
1,1,2,2,2,2,2,2,2,2,2,2,2,2,2,2,2,2,1,1
1,1,2,2,2,2,2,2,2,2,2,2,2,2,2,2,2,2,1,1
1,1,2,2,2,2,2,2,2,2,2,2,2,2,2,2,2,2,1,1
1,1,2,2,2,2,2,2,2,2,2,2,2,2,2,2,2,2,1,1
1,1,2,2,2,2,2,2,2,2,2,2,2,2,2,2,2,2,1,1
1,1,2,2,2,2,2,2,2,2,2,2,2,2,2,2,2,2,1,1
1,1,2,2,2,2,2,2,2,2,2,2,2,2,2,2,2,2,1,1
1,1,2,2,2,2,2,2,2,2,2,2,2,2,2,2,2,2,1,1
1,1,2,2,2,2,2,2,2,2,2,2,2,2,2,2,2,2,1,1
1,1,2,2,2,2,2,2,2,2,2,2,2,2,2,1,1,1,1,1
1,1,2,2,2,2,2,2,2,2,2,2,2,2,2,1,1,1,1,1
1,1,1,1,1,2,3,2,2,2,2,2,2,3,2,1,1,1,1,1
1,1,1,1,1,1,1,1,1,1,1,1,1,1,1,1,1,1,1,1
endlayer

layer
1,1,1,1,1,1,1,1,1,1,1,1,1,1,1,1,1,1,1,1
1,1,1,1,1,1,1,1,1,1,1,1,1,1,1,1,1,1,1,1
1,1,1,1,1,1,1,1,1,1,1,1,1,1,1,1,1,1,1,1
1,1,1,1,1,1,1,1,1,1,1,1,1,1,1,1,1,1,1,1
1,1,1,1,1,1,1,1,1,2,2,1,1,1,1,1,1,1,1,1
1,1,1,1,1,1,1,1,2,4,4,2,1,1,1,1,1,1,1,1
1,1,1,1,1,1,1,1,2,5,5,2,1,1,1,1,1,1,1,1
1,1,1,1,1,1,1,1,2,5,5,2,1,1,1,1,1,1,1,1
1,1,1,1,1,1,2,2,2,6,6,2,2,2,1,1,1,1,1,1
1,1,1,1,1,2,7,6,6,6,6,6,6,7,2,1,1,1,1,1
1,1,2,2,2,2,6,6,6,6,6,6,6,6,2,2,2,2,1,1
1,2,8,8,6,6,6,6,6,6,6,6,6,6,6,6,6,8,2,1
1,2,6,6,6,6,6,6,6,9,9,6,6,6,6,6,6,6,2,1
1,2,6,6,6,6,6,6,12,11,11,10,6,6,6,6,6,6,2,1
1,2,6,20,6,2,6,6,12,11,11,10,6,6,2,6,6,6,2,1
1,2,6,6,6,2,6,6,12,11,11,10,6,6,2,6,6,6,2,1
1,2,6,6,6,6,6,6,12,11,11,10,6,6,2,6,13,6,2,1
1,2,14,6,6,6,6,6,12,11,11,10,6,6,2,6,6,6,2,1
1,2,6,6,6,6,6,6,12,11,11,10,6,6,2,6,6,6,2,1
1,2,6,6,6,2,6,6,12,11,11,10,6,6,6,6,6,6,2,1
1,2,6,21,6,2,6,6,6,15,15,6,6,6,6,6,6,6,2,1
1,2,6,6,6,6,6,6,6,6,6,6,6,6,6,6,6,16,2,1
1,2,6,6,6,6,6,6,17,17,17,17,6,6,2,2,2,2,1,1
1,2,16,16,6,6,6,6,17,6,6,17,6,6,2,1,1,1,1,1
1,1,2,2,2,2,6,6,6,18,18,6,6,6,2,1,1,1,1,1
1,1,1,1,1,1,2,2,2,2,2,2,2,2,1,1,1,1,1,1
endlayer

layer
1,1,1,1,1,1,1,1,1,1,1,1,1,1,1,1,1,1,1,1
1,1,1,1,1,1,1,1,1,1,1,1,1,1,1,1,1,1,1,1
1,1,1,1,1,1,1,1,1,1,1,1,1,1,1,1,1,1,1,1
1,1,1,1,1,1,1,1,1,1,1,1,1,1,1,1,1,1,1,1
1,1,1,1,1,1,1,1,1,2,2,1,1,1,1,1,1,1,1,1
1,1,1,1,1,1,1,1,2,4,4,2,1,1,1,1,1,1,1,1
1,1,1,1,1,1,1,1,2,5,5,2,1,1,1,1,1,1,1,1
1,1,1,1,1,1,1,1,2,5,5,2,1,1,1,1,1,1,1,1
1,1,1,1,1,1,2,2,2,6,6,2,2,2,1,1,1,1,1,1
1,1,1,1,1,2,7,6,6,6,6,6,6,7,2,1,1,1,1,1
1,1,2,2,2,2,6,6,6,6,6,6,6,6,2,2,2,2,1,1
1,2,6,6,6,6,6,6,6,6,6,6,6,6,6,6,6,6,2,1
1,2,6,6,6,6,6,6,6,6,6,6,6,6,6,6,6,6,2,1
1,2,6,6,6,6,6,6,6,19,19,6,6,6,6,6,6,6,2,1
1,2,6,6,6,2,6,6,6,19,19,6,6,6,2,6,6,6,2,1
1,2,6,6,6,2,6,6,6,19,19,6,6,6,2,6,6,6,2,1
1,2,6,6,6,6,6,6,6,19,19,6,6,6,2,6,6,6,2,1
1,2,6,6,6,6,6,6,6,19,19,6,6,6,2,6,6,6,2,1
1,2,6,6,6,6,6,6,6,19,19,6,6,6,2,6,6,6,2,1
1,2,6,6,6,2,6,6,6,19,19,6,6,6,6,6,6,6,2,1
1,2,6,6,6,2,6,6,6,6,6,6,6,6,6,6,6,6,2,1
1,2,6,6,6,6,6,6,6,6,6,6,6,6,6,6,6,6,2,1
1,2,6,6,6,6,6,6,17,17,17,17,6,6,2,2,2,2,1,1
1,2,6,6,6,6,6,6,17,6,6,17,6,6,2,1,1,1,1,1
1,1,2,2,2,2,6,6,6,18,18,6,6,6,2,1,1,1,1,1
1,1,1,1,1,1,2,2,2,2,2,2,2,2,1,1,1,1,1,1
endlayer

layer
1,1,1,1,1,1,1,1,1,1,1,1,1,1,1,1,1,1,1,1
1,1,1,1,1,1,1,1,1,1,1,1,1,1,1,1,1,1,1,1
1,1,1,1,1,1,1,1,1,1,1,1,1,1,1,1,1,1,1,1
1,1,1,1,1,1,1,1,1,1,1,1,1,1,1,1,1,1,1,1
1,1,1,1,1,1,1,1,1,2,2,1,1,1,1,1,1,1,1,1
1,1,1,1,1,1,1,1,2,22,22,2,1,1,1,1,1,1,1,1
1,1,1,1,1,1,1,1,2,6,6,2,1,1,1,1,1,1,1,1
1,1,1,1,1,1,1,1,2,6,6,2,1,1,1,1,1,1,1,1
1,1,1,1,1,1,2,2,2,24,23,2,2,2,1,1,1,1,1,1
1,1,1,1,1,2,7,6,6,6,6,6,6,7,2,1,1,1,1,1
1,1,2,2,2,2,6,6,6,6,6,6,6,6,2,2,2,2,1,1
1,2,6,6,6,22,6,6,6,6,6,6,6,6,22,6,6,6,2,1
1,2,6,6,6,6,6,6,6,6,6,6,6,6,6,6,6,6,2,1
1,2,6,6,6,25,6,6,6,6,6,6,6,6,25,6,6,6,2,1
1,2,6,6,6,2,6,6,6,6,6,6,6,6,2,6,6,6,2,1
1,2,6,6,6,2,6,6,6,6,6,6,6,6,2,6,6,6,2,1
1,2,6,6,6,22,6,6,6,6,6,6,6,6,2,6,6,6,2,1
1,2,6,6,6,6,6,6,6,6,6,6,6,6,2,6,6,6,2,1
1,2,6,6,6,25,6,6,6,6,6,6,6,6,2,6,6,6,2,1
1,2,6,6,6,2,6,6,6,6,6,6,6,6,22,6,6,6,2,1
1,2,6,6,6,2,6,6,6,6,6,6,6,6,6,6,6,6,2,1
1,2,6,6,6,22,6,6,6,6,6,6,6,6,25,6,6,6,2,1
1,2,6,6,6,6,6,6,17,17,17,17,6,6,2,2,2,2,1,1
1,2,6,6,6,25,6,6,17,6,6,17,6,6,2,1,1,1,1,1
1,1,2,2,2,2,6,6,6,18,18,6,6,6,2,1,1,1,1,1
1,1,1,1,1,1,2,2,2,2,2,2,2,2,1,1,1,1,1,1
endlayer

layer
1,1,1,1,1,1,1,1,1,1,1,1,1,1,1,1,1,1,1,1
1,1,1,1,1,1,1,1,1,1,1,1,1,1,1,1,1,1,1,1
1,1,1,1,1,1,1,1,1,1,1,1,1,1,1,1,1,1,1,1
1,1,1,1,1,1,1,1,1,1,1,1,1,1,1,1,1,1,1,1
1,1,1,1,1,1,1,1,1,1,1,1,1,1,1,1,1,1,1,1
1,1,1,1,1,1,1,1,1,2,2,1,1,1,1,1,1,1,1,1
1,1,1,1,1,1,1,1,1,2,2,1,1,1,1,1,1,1,1,1
1,1,1,1,1,1,1,1,1,2,2,1,1,1,1,1,1,1,1,1
1,1,1,1,1,1,2,2,2,2,2,2,2,2,1,1,1,1,1,1
1,1,1,1,1,2,3,27,6,6,6,6,26,3,2,1,1,1,1,1
1,1,1,1,1,2,28,6,6,6,6,6,6,28,2,1,1,1,1,1
1,1,2,2,2,2,6,6,6,6,6,6,6,6,2,2,2,2,1,1
1,1,2,2,2,2,6,6,6,6,6,6,6,6,2,2,2,2,1,1
1,1,2,2,2,2,6,6,6,6,6,6,6,6,2,2,2,2,1,1
1,1,2,2,2,2,6,6,6,6,6,6,6,6,2,2,2,2,1,1
1,1,2,2,2,2,6,6,6,6,6,6,6,6,2,2,2,2,1,1
1,1,2,2,2,2,6,6,6,6,6,6,6,6,2,2,2,2,1,1
1,1,2,2,2,2,6,6,6,6,6,6,6,6,2,2,2,2,1,1
1,1,2,2,2,2,6,6,6,6,6,6,6,6,2,2,2,2,1,1
1,1,2,2,2,2,6,6,6,6,6,6,6,6,2,2,2,2,1,1
1,1,2,2,2,2,6,6,6,6,6,6,6,6,2,2,2,2,1,1
1,1,2,2,2,2,6,6,6,6,6,6,6,6,2,2,2,2,1,1
1,1,2,2,2,2,6,6,17,17,17,17,6,6,2,1,1,1,1,1
1,1,2,2,2,2,6,6,17,6,6,17,6,6,2,1,1,1,1,1
1,1,1,1,1,2,6,6,6,18,18,6,6,6,2,1,1,1,1,1
1,1,1,1,1,1,2,2,2,2,2,2,2,2,1,1,1,1,1,1
endlayer

layer
1,1,1,1,1,1,1,1,1,1,1,1,1,1,1,1,1,1,1,1
1,1,1,1,1,1,1,1,1,1,1,1,1,1,1,1,1,1,1,1
1,1,1,1,1,1,1,1,1,1,1,1,1,1,1,1,1,1,1,1
1,1,1,1,1,1,1,1,1,1,1,1,1,1,1,1,1,1,1,1
1,1,1,1,1,1,1,1,1,1,1,1,1,1,1,1,1,1,1,1
1,1,1,1,1,1,1,1,1,1,1,1,1,1,1,1,1,1,1,1
1,1,1,1,1,1,1,1,1,1,1,1,1,1,1,1,1,1,1,1
1,1,1,1,1,1,1,1,1,1,1,1,1,1,1,1,1,1,1,1
1,1,1,1,1,1,2,2,2,2,2,2,2,2,1,1,1,1,1,1
1,1,1,1,1,2,3,2,2,2,2,2,2,3,2,1,1,1,1,1
1,29,29,29,29,2,2,2,2,2,2,2,2,2,2,29,29,29,29,1
1,29,29,29,29,2,2,2,2,2,2,2,2,2,2,29,29,29,29,1
1,29,29,29,29,2,2,2,6,6,6,6,2,2,2,29,29,29,29,1
1,29,29,29,29,2,2,2,6,6,6,6,2,2,2,29,29,29,29,1
1,29,29,29,29,2,2,2,6,6,6,6,2,2,2,29,29,29,29,1
1,29,29,29,29,2,2,2,6,6,6,6,2,2,2,29,29,29,29,1
1,29,29,29,29,2,2,2,6,6,6,6,2,2,2,29,29,29,29,1
1,29,29,29,29,2,2,2,6,6,6,6,2,2,2,29,29,29,29,1
1,29,29,29,29,2,2,2,6,6,6,6,2,2,2,29,29,29,29,1
1,29,29,29,29,2,2,2,6,6,6,6,2,2,2,29,29,29,29,1
1,29,29,29,29,2,2,2,6,6,6,6,2,2,2,29,29,29,29,1
1,29,29,29,29,2,2,2,6,6,6,6,2,2,2,29,29,29,29,1
1,29,29,29,29,2,2,2,2,2,2,2,2,2,2,29,29,29,29,1
1,29,29,29,29,2,2,2,2,2,2,2,2,2,2,29,29,29,29,1
1,1,1,1,1,2,3,2,2,18,18,2,2,3,2,1,1,1,1,1
1,1,1,1,1,1,2,2,2,2,2,2,2,2,1,1,1,1,1,1
endlayer

layer
1,1,1,1,1,1,1,1,1,1,1,1,1,1,1,1,1,1,1,1
1,1,1,1,1,1,1,1,1,1,1,1,1,1,1,1,1,1,1,1
1,1,1,1,1,1,1,1,1,1,1,1,1,1,1,1,1,1,1,1
1,1,1,1,1,1,1,1,1,1,1,1,1,1,1,1,1,1,1,1
1,1,1,1,1,1,1,1,1,1,1,1,1,1,1,1,1,1,1,1
1,1,1,1,1,1,1,1,1,1,1,1,1,1,1,1,1,1,1,1
1,1,1,1,1,1,1,1,1,1,1,1,1,1,1,1,1,1,1,1
1,1,1,1,1,1,1,1,1,1,1,1,1,1,1,1,1,1,1,1
1,1,1,1,1,1,2,2,2,2,2,2,2,2,1,1,1,1,1,1
1,29,29,29,29,2,7,6,6,6,6,6,6,7,2,29,29,29,29,1
29,34,6,6,33,2,6,6,6,6,6,6,6,6,2,32,31,6,30,29
29,14,6,6,6,35,6,17,17,17,17,17,17,6,2,14,6,6,13,29
29,13,6,6,36,2,6,17,6,6,6,6,17,6,37,6,6,6,36,29
29,30,6,40,39,2,6,17,6,6,6,6,17,6,2,33,6,6,38,29
29,29,29,29,29,2,6,17,6,6,6,6,17,6,2,29,29,29,29,29
29,34,6,6,33,2,6,17,6,6,6,6,17,6,2,32,31,6,30,29
29,14,6,6,6,35,6,17,6,6,6,6,17,6,2,14,6,6,13,29
29,13,6,6,36,2,6,17,6,6,6,6,17,6,37,6,6,6,36,29
29,30,6,40,39,2,6,17,6,6,6,6,17,6,2,33,6,6,38,29
29,29,29,29,29,2,6,17,6,6,6,6,17,6,2,29,29,29,29,29
29,34,6,6,33,2,6,17,6,6,6,6,17,6,2,32,31,6,30,29
29,14,6,6,6,35,6,17,6,6,6,6,17,6,2,14,6,6,13,29
29,13,6,6,36,2,41,17,17,17,17,17,17,6,37,6,6,6,36,29
29,30,6,40,39,2,43,6,6,6,6,6,6,42,2,33,6,6,38,29
1,29,29,29,29,2,44,43,6,18,18,42,45,44,2,29,29,29,29,1
1,1,1,1,1,1,2,2,2,2,2,2,2,2,1,1,1,1,1,1
endlayer

layer
1,1,1,1,1,1,1,1,1,1,1,1,1,1,1,1,1,1,1,1
1,1,1,1,1,1,1,1,1,1,1,1,1,1,1,1,1,1,1,1
1,1,1,1,1,1,1,1,1,1,1,1,1,1,1,1,1,1,1,1
1,1,1,1,1,1,1,1,1,1,1,1,1,1,1,1,1,1,1,1
1,1,1,1,1,1,1,1,1,1,1,1,1,1,1,1,1,1,1,1
1,1,1,1,1,1,1,1,1,1,1,1,1,1,1,1,1,1,1,1
1,1,1,1,1,1,1,1,1,1,1,1,1,1,1,1,1,1,1,1
1,1,1,1,1,1,1,1,1,1,1,1,1,1,1,1,1,1,1,1
1,1,1,1,1,1,2,2,2,2,2,2,2,2,1,1,1,1,1,1
1,29,29,29,29,2,7,6,6,6,6,6,6,7,2,29,29,29,29,1
29,6,6,6,33,2,6,6,6,6,6,6,6,6,2,6,6,6,6,29
29,6,6,6,6,46,6,6,6,6,6,6,6,6,2,6,6,6,6,29
29,6,6,6,6,2,6,6,6,6,6,6,6,6,46,6,6,6,6,29
29,6,6,6,6,2,6,6,6,6,6,6,6,6,2,33,6,6,6,29
29,29,29,29,29,2,6,6,6,6,6,6,6,6,2,29,29,29,29,29
29,6,6,6,33,2,6,6,6,6,6,6,6,6,2,6,6,6,6,29
29,6,6,6,6,46,6,6,6,6,6,6,6,6,2,6,6,6,6,29
29,6,6,6,6,2,6,6,6,6,6,6,6,6,46,6,6,6,6,29
29,6,6,6,6,2,6,6,6,6,6,6,6,6,2,33,6,6,6,29
29,29,29,29,29,2,6,6,6,6,6,6,6,6,2,29,29,29,29,29
29,6,6,6,33,2,6,6,6,6,6,6,6,6,2,6,6,6,6,29
29,6,6,6,6,46,6,6,6,6,6,6,6,6,2,6,6,6,6,29
29,6,6,6,6,2,41,6,17,17,17,17,6,6,46,6,6,6,6,29
29,6,6,6,6,2,43,6,6,6,6,6,6,42,2,33,6,6,6,29
1,29,29,29,29,2,44,43,6,18,18,42,45,44,2,29,29,29,29,1
1,1,1,1,1,1,2,2,2,2,2,2,2,2,1,1,1,1,1,1
endlayer

layer
1,1,1,1,1,1,1,1,1,1,1,1,1,1,1,1,1,1,1,1
1,1,1,1,1,1,1,1,1,1,1,1,1,1,1,1,1,1,1,1
1,1,1,1,1,1,1,1,1,1,1,1,1,1,1,1,1,1,1,1
1,1,1,1,1,1,1,1,1,1,1,1,1,1,1,1,1,1,1,1
1,1,1,1,1,1,1,1,1,1,1,1,1,1,1,1,1,1,1,1
1,1,1,1,1,1,1,1,1,1,1,1,1,1,1,1,1,1,1,1
1,1,1,1,1,1,1,1,1,1,1,1,1,1,1,1,1,1,1,1
1,1,1,1,1,1,1,1,1,1,1,1,1,1,1,1,1,1,1,1
1,1,1,1,1,1,2,2,2,2,2,2,2,2,1,1,1,1,1,1
1,29,29,29,29,2,7,6,6,6,6,6,6,7,2,29,29,29,29,1
29,6,6,6,6,2,6,6,6,6,6,6,6,6,2,6,6,6,6,29
29,6,6,6,6,2,6,6,6,6,6,6,6,6,2,6,6,6,6,29
29,6,6,6,6,2,6,6,6,6,6,6,6,6,2,6,6,6,6,29
29,6,6,6,6,2,6,6,6,6,6,6,6,6,2,6,6,6,6,29
29,29,29,29,29,2,6,6,6,6,6,6,6,6,2,29,29,29,29,29
29,6,6,6,6,2,6,6,6,6,6,6,6,6,2,6,6,6,6,29
29,6,6,6,6,2,6,6,6,6,6,6,6,6,2,6,6,6,6,29
29,6,6,6,6,2,6,6,6,6,6,6,6,6,2,6,6,6,6,29
29,6,6,6,6,2,6,6,6,6,6,6,6,6,2,6,6,6,6,29
29,29,29,29,29,2,6,6,6,6,6,6,6,6,2,29,29,29,29,29
29,6,6,6,6,2,6,6,6,6,6,6,6,6,2,6,6,6,6,29
29,6,6,6,6,2,6,6,6,6,6,6,6,6,2,6,6,6,6,29
29,6,6,6,6,2,41,6,17,17,17,17,6,6,2,6,6,6,6,29
29,6,6,6,6,2,43,6,6,6,6,6,6,42,2,6,6,6,6,29
1,29,29,29,29,2,44,43,6,18,18,42,47,44,2,29,29,29,29,1
1,1,1,1,1,1,2,2,2,2,2,2,2,2,1,1,1,1,1,1
endlayer

layer
1,1,1,1,1,1,1,1,1,1,1,1,1,1,1,1,1,1,1,1
1,1,1,1,1,1,1,1,1,1,1,1,1,1,1,1,1,1,1,1
1,1,1,1,1,1,1,1,1,1,1,1,1,1,1,1,1,1,1,1
1,1,1,1,1,1,1,1,1,1,1,1,1,1,1,1,1,1,1,1
1,1,1,1,1,1,1,1,1,1,1,1,1,1,1,1,1,1,1,1
1,1,1,1,1,1,1,1,1,1,1,1,1,1,1,1,1,1,1,1
1,1,1,1,1,1,1,1,1,1,1,1,1,1,1,1,1,1,1,1
1,1,1,1,1,1,1,1,1,1,1,1,1,1,1,1,1,1,1,1
1,1,1,1,1,1,2,2,2,2,2,2,2,2,1,1,1,1,1,1
1,1,1,1,1,2,3,2,2,2,2,2,2,3,2,1,1,1,1,1
1,29,29,29,29,2,2,2,2,2,2,2,2,2,2,29,29,29,29,1
1,29,29,29,29,2,2,2,2,2,2,2,2,2,2,29,29,29,29,1
1,29,29,29,29,2,2,2,6,6,6,6,2,2,2,29,29,29,29,1
1,29,29,29,29,2,2,2,6,6,6,6,2,2,2,29,29,29,29,1
1,29,29,29,29,2,2,2,6,6,6,6,2,2,2,29,29,29,29,1
1,29,29,29,29,2,2,2,6,6,6,6,2,2,2,29,29,29,29,1
1,29,29,29,29,2,2,2,6,6,6,6,2,2,2,29,29,29,29,1
1,29,29,29,29,2,2,2,6,6,6,6,2,2,2,29,29,29,29,1
1,29,29,29,29,2,2,2,6,6,6,6,2,2,2,29,29,29,29,1
1,29,29,29,29,2,2,2,6,6,6,6,2,2,2,29,29,29,29,1
1,29,29,29,29,2,2,2,6,6,6,6,2,2,2,29,29,29,29,1
1,29,29,29,29,2,2,2,6,6,6,6,2,2,2,29,29,29,29,1
1,29,29,29,29,2,2,2,2,2,2,2,2,2,2,29,29,29,29,1
1,29,29,29,29,2,2,2,2,2,2,2,2,2,2,29,29,29,29,1
1,1,1,1,1,2,3,2,2,18,18,2,2,3,2,1,1,1,1,1
1,1,1,1,1,1,2,2,2,2,2,2,2,2,1,1,1,1,1,1
endlayer

layer
1,1,1,1,1,1,1,1,1,1,1,1,1,1,1,1,1,1,1,1
1,1,1,1,1,1,1,1,1,1,1,1,1,1,1,1,1,1,1,1
1,1,1,1,1,1,1,1,1,1,1,1,1,1,1,1,1,1,1,1
1,1,1,1,1,1,1,1,1,1,1,1,1,1,1,1,1,1,1,1
1,1,1,1,1,1,1,1,1,1,1,1,1,1,1,1,1,1,1,1
1,1,1,1,1,1,1,1,1,1,1,1,1,1,1,1,1,1,1,1
1,1,1,1,1,1,1,1,1,1,1,1,1,1,1,1,1,1,1,1
1,1,1,1,1,1,1,1,1,1,1,1,1,1,1,1,1,1,1,1
1,1,1,1,1,1,2,2,2,2,2,2,2,2,1,1,1,1,1,1
1,29,29,29,29,2,7,6,6,6,6,6,6,7,2,29,29,29,29,1
29,34,6,6,33,2,6,6,6,6,6,6,6,6,2,32,31,6,30,29
29,14,6,6,6,35,6,17,17,17,17,17,17,6,2,14,6,6,13,29
29,13,6,6,36,2,6,17,6,6,6,6,17,6,37,6,6,6,36,29
29,30,6,40,39,2,6,17,6,6,6,6,17,6,2,33,6,6,38,29
29,29,29,29,29,2,6,17,6,6,6,6,17,6,2,29,29,29,29,29
29,34,6,6,33,2,6,17,6,6,6,6,17,6,2,32,31,6,30,29
29,14,6,6,6,35,6,17,6,6,6,6,17,6,2,14,6,6,13,29
29,13,6,6,36,2,6,17,6,6,6,6,17,6,37,6,6,6,36,29
29,30,6,40,39,2,6,17,6,6,6,6,17,6,2,33,6,6,38,29
29,29,29,29,29,2,6,17,6,6,6,6,17,6,2,29,29,29,29,29
29,34,6,6,33,2,6,17,6,6,6,6,17,6,2,32,31,6,30,29
29,14,6,6,6,35,6,17,6,6,6,6,17,6,2,14,6,6,13,29
29,13,6,6,36,2,41,17,17,17,17,17,17,6,37,6,6,6,36,29
29,30,6,40,39,2,43,6,6,6,6,6,6,42,2,33,6,6,38,29
1,29,29,29,29,2,44,43,6,18,18,42,45,44,2,29,29,29,29,1
1,1,1,1,1,1,2,2,2,2,2,2,2,2,1,1,1,1,1,1
endlayer

layer
1,1,1,1,1,1,1,1,1,1,1,1,1,1,1,1,1,1,1,1
1,1,1,1,1,1,1,1,1,1,1,1,1,1,1,1,1,1,1,1
1,1,1,1,1,1,1,1,1,1,1,1,1,1,1,1,1,1,1,1
1,1,1,1,1,1,1,1,1,1,1,1,1,1,1,1,1,1,1,1
1,1,1,1,1,1,1,1,1,1,1,1,1,1,1,1,1,1,1,1
1,1,1,1,1,1,1,1,1,1,1,1,1,1,1,1,1,1,1,1
1,1,1,1,1,1,1,1,1,1,1,1,1,1,1,1,1,1,1,1
1,1,1,1,1,1,1,1,1,1,1,1,1,1,1,1,1,1,1,1
1,1,1,1,1,1,2,2,2,2,2,2,2,2,1,1,1,1,1,1
1,29,29,29,29,2,7,6,6,6,6,6,6,7,2,29,29,29,29,1
29,6,6,6,33,2,6,6,6,6,6,6,6,6,2,6,6,6,6,29
29,6,6,6,6,46,6,6,6,6,6,6,6,6,2,6,6,6,6,29
29,6,6,6,6,2,6,6,6,6,6,6,6,6,46,6,6,6,6,29
29,6,6,6,6,2,6,6,6,6,6,6,6,6,2,33,6,6,6,29
29,29,29,29,29,2,6,6,6,6,6,6,6,6,2,29,29,29,29,29
29,6,6,6,33,2,6,6,6,6,6,6,6,6,2,6,6,6,6,29
29,6,6,6,6,46,6,6,6,6,6,6,6,6,2,6,6,6,6,29
29,6,6,6,6,2,6,6,6,6,6,6,6,6,46,6,6,6,6,29
29,6,6,6,6,2,6,6,6,6,6,6,6,6,2,33,6,6,6,29
29,29,29,29,29,2,6,6,6,6,6,6,6,6,2,29,29,29,29,29
29,6,6,6,33,2,6,6,6,6,6,6,6,6,2,6,6,6,6,29
29,6,6,6,6,46,6,6,6,6,6,6,6,6,2,6,6,6,6,29
29,6,6,6,6,2,41,6,17,17,17,17,6,6,46,6,6,6,6,29
29,6,6,6,6,2,43,6,6,6,6,6,6,42,2,33,6,6,6,29
1,29,29,29,29,2,44,41,6,18,18,42,47,44,2,29,29,29,29,1
1,1,1,1,1,1,2,2,2,2,2,2,2,2,1,1,1,1,1,1
endlayer

layer
1,1,1,1,1,1,1,1,1,1,1,1,1,1,1,1,1,1,1,1
1,1,1,1,1,1,1,1,1,1,1,1,1,1,1,1,1,1,1,1
1,1,1,1,1,1,1,1,1,1,1,1,1,1,1,1,1,1,1,1
1,1,1,1,1,1,1,1,1,1,1,1,1,1,1,1,1,1,1,1
1,1,1,1,1,1,1,1,1,1,1,1,1,1,1,1,1,1,1,1
1,1,1,1,1,1,1,1,1,1,1,1,1,1,1,1,1,1,1,1
1,1,1,1,1,1,1,1,1,1,1,1,1,1,1,1,1,1,1,1
1,1,1,1,1,1,1,1,1,1,1,1,1,1,1,1,1,1,1,1
1,1,1,1,1,1,2,2,2,2,2,2,2,2,1,1,1,1,1,1
1,29,29,29,29,2,7,6,6,6,6,6,6,7,2,29,29,29,29,1
29,6,6,6,6,2,6,6,6,6,6,6,6,6,2,6,6,6,6,29
29,6,6,6,6,2,6,6,6,6,6,6,6,6,2,6,6,6,6,29
29,6,6,6,6,2,6,6,6,6,6,6,6,6,2,6,6,6,6,29
29,6,6,6,6,2,6,6,6,6,6,6,6,6,2,6,6,6,6,29
29,29,29,29,29,2,6,6,6,6,6,6,6,6,2,29,29,29,29,29
29,6,6,6,6,2,6,6,6,6,6,6,6,6,2,6,6,6,6,29
29,6,6,6,6,2,6,6,6,6,6,6,6,6,2,6,6,6,6,29
29,6,6,6,6,2,6,6,6,6,6,6,6,6,2,6,6,6,6,29
29,6,6,6,6,2,6,6,6,6,6,6,6,6,2,6,6,6,6,29
29,29,29,29,29,2,6,6,6,6,6,6,6,6,2,29,29,29,29,29
29,6,6,6,6,2,6,6,6,6,6,6,6,6,2,6,6,6,6,29
29,6,6,6,6,2,6,6,6,6,6,6,6,6,2,6,6,6,6,29
29,6,6,6,6,2,41,6,17,17,17,17,6,6,2,6,6,6,6,29
29,6,6,6,6,2,43,6,6,6,6,6,6,42,2,6,6,6,6,29
1,29,29,29,29,2,44,41,6,18,18,42,47,44,2,29,29,29,29,1
1,1,1,1,1,1,2,2,2,2,2,2,2,2,1,1,1,1,1,1
endlayer

layer
1,1,1,1,1,1,1,1,1,1,1,1,1,1,1,1,1,1,1,1
1,1,1,1,1,1,1,1,1,1,1,1,1,1,1,1,1,1,1,1
1,1,1,1,1,1,1,1,1,1,1,1,1,1,1,1,1,1,1,1
1,1,1,1,1,1,1,1,1,1,1,1,1,1,1,1,1,1,1,1
1,1,1,1,1,1,1,1,1,1,1,1,1,1,1,1,1,1,1,1
1,1,1,1,1,1,1,1,1,1,1,1,1,1,1,1,1,1,1,1
1,1,1,1,1,1,1,1,1,1,1,1,1,1,1,1,1,1,1,1
1,1,1,1,1,1,1,1,1,1,1,1,1,1,1,1,1,1,1,1
1,1,1,1,1,1,2,2,2,2,2,2,2,2,1,1,1,1,1,1
1,1,1,1,1,2,3,2,2,2,2,2,2,3,2,1,1,1,1,1
1,29,29,29,29,2,2,2,2,2,2,2,2,2,2,29,29,29,29,1
1,29,29,29,29,2,2,2,2,2,2,2,2,2,2,29,29,29,29,1
1,29,29,29,29,2,2,2,6,6,6,6,2,2,2,29,29,29,29,1
1,29,29,29,29,2,2,2,6,6,6,6,2,2,2,29,29,29,29,1
1,29,29,29,29,2,2,2,6,6,6,6,2,2,2,29,29,29,29,1
1,29,29,29,29,2,2,2,6,6,6,6,2,2,2,29,29,29,29,1
1,29,29,29,29,2,2,2,6,6,6,6,2,2,2,29,29,29,29,1
1,29,29,29,29,2,2,2,6,6,6,6,2,2,2,29,29,29,29,1
1,29,29,29,29,2,2,2,6,6,6,6,2,2,2,29,29,29,29,1
1,29,29,29,29,2,2,2,6,6,6,6,2,2,2,29,29,29,29,1
1,29,29,29,29,2,2,2,6,6,6,6,2,2,2,29,29,29,29,1
1,29,29,29,29,2,2,2,6,6,6,6,2,2,2,29,29,29,29,1
1,29,29,29,29,2,2,2,2,2,2,2,2,2,2,29,29,29,29,1
1,29,29,29,29,2,2,2,2,2,2,2,2,2,2,29,29,29,29,1
1,1,1,1,1,2,3,2,2,18,18,2,2,3,2,1,1,1,1,1
1,1,1,1,1,1,2,2,2,2,2,2,2,2,1,1,1,1,1,1
endlayer

layer
1,1,1,1,1,1,1,1,1,1,1,1,1,1,1,1,1,1,1,1
1,1,1,1,1,1,1,1,1,1,1,1,1,1,1,1,1,1,1,1
1,1,1,1,1,1,1,1,1,1,1,1,1,1,1,1,1,1,1,1
1,1,1,1,1,1,1,1,1,1,1,1,1,1,1,1,1,1,1,1
1,1,1,1,1,1,1,1,1,1,1,1,1,1,1,1,1,1,1,1
1,1,1,1,1,1,1,1,1,1,1,1,1,1,1,1,1,1,1,1
1,1,1,1,1,1,1,1,1,1,1,1,1,1,1,1,1,1,1,1
1,1,1,1,1,1,1,1,1,1,1,1,1,1,1,1,1,1,1,1
1,1,1,1,1,1,2,2,2,2,2,2,2,2,1,1,1,1,1,1
1,29,29,29,29,2,7,6,6,6,6,6,6,7,2,29,29,29,29,1
29,34,6,6,33,2,6,6,6,6,6,6,6,6,2,32,31,6,30,29
29,14,6,6,6,35,6,17,17,17,17,17,17,6,2,14,6,6,13,29
29,13,6,6,36,2,6,17,6,6,6,6,17,6,37,6,6,6,36,29
29,30,6,40,39,2,6,17,6,6,6,6,17,6,2,33,6,6,38,29
29,29,29,29,29,2,6,17,6,6,6,6,17,6,2,29,29,29,29,29
29,34,6,6,33,2,6,17,6,6,6,6,17,6,2,32,31,6,30,29
29,14,6,6,6,35,6,17,6,6,6,6,17,6,2,14,6,6,13,29
29,13,6,6,36,2,6,17,6,6,6,6,17,6,37,6,6,6,36,29
29,30,6,40,39,2,6,17,6,6,6,6,17,6,2,33,6,6,38,29
29,29,29,29,29,2,6,17,6,6,6,6,17,6,2,29,29,29,29,29
29,34,6,6,33,2,6,17,6,6,6,6,17,6,2,32,31,6,30,29
29,14,6,6,6,35,6,17,6,6,6,6,17,6,2,14,6,6,13,29
29,13,6,6,36,2,6,17,17,17,17,17,17,6,37,6,6,6,36,29
29,30,6,40,39,2,43,6,6,6,6,6,6,48,2,33,6,6,38,29
1,29,29,29,29,2,49,43,42,18,18,6,47,44,2,29,29,29,29,1
1,1,1,1,1,1,2,2,2,2,2,2,2,2,1,1,1,1,1,1
endlayer

layer
1,1,1,1,1,1,1,1,1,1,1,1,1,1,1,1,1,1,1,1
1,1,1,1,1,1,1,1,1,1,1,1,1,1,1,1,1,1,1,1
1,1,1,1,1,1,1,1,1,1,1,1,1,1,1,1,1,1,1,1
1,1,1,1,1,1,1,1,1,1,1,1,1,1,1,1,1,1,1,1
1,1,1,1,1,1,1,1,1,1,1,1,1,1,1,1,1,1,1,1
1,1,1,1,1,1,1,1,1,1,1,1,1,1,1,1,1,1,1,1
1,1,1,1,1,1,1,1,1,1,1,1,1,1,1,1,1,1,1,1
1,1,1,1,1,1,1,1,1,1,1,1,1,1,1,1,1,1,1,1
1,1,1,1,1,1,2,2,2,2,2,2,2,2,1,1,1,1,1,1
1,29,29,29,29,2,7,6,6,6,6,6,6,7,2,29,29,29,29,1
29,6,6,6,33,2,6,6,6,6,6,6,6,6,2,6,6,6,6,29
29,6,6,6,6,46,6,6,6,6,6,6,6,6,2,6,6,6,6,29
29,6,6,6,6,2,6,6,6,6,6,6,6,6,46,6,6,6,6,29
29,6,6,6,6,2,6,6,6,6,6,6,6,6,2,33,6,6,6,29
29,29,29,29,29,2,6,6,6,6,6,6,6,6,2,29,29,29,29,29
29,6,6,6,33,2,6,6,6,6,6,6,6,6,2,6,6,6,6,29
29,6,6,6,6,46,6,6,6,6,6,6,6,6,2,6,6,6,6,29
29,6,6,6,6,2,6,6,6,6,6,6,6,6,46,6,6,6,6,29
29,6,6,6,6,2,6,6,6,6,6,6,6,6,2,33,6,6,6,29
29,29,29,29,29,2,6,6,6,6,6,6,6,6,2,29,29,29,29,29
29,6,6,6,33,2,6,6,6,6,6,6,6,6,2,6,6,6,6,29
29,6,6,6,6,46,6,6,6,6,6,6,6,6,2,6,6,6,6,29
29,6,6,6,6,2,6,6,17,17,17,17,6,6,46,6,6,6,6,29
29,6,6,6,6,2,43,6,6,6,6,6,6,45,2,33,6,6,6,29
1,29,29,29,29,2,49,43,42,18,18,6,47,44,2,29,29,29,29,1
1,1,1,1,1,1,2,2,2,2,2,2,2,2,1,1,1,1,1,1
endlayer

layer
1,1,1,1,1,1,1,1,1,1,1,1,1,1,1,1,1,1,1,1
1,1,1,1,1,1,1,1,1,1,1,1,1,1,1,1,1,1,1,1
1,1,1,1,1,1,1,1,1,1,1,1,1,1,1,1,1,1,1,1
1,1,1,1,1,1,1,1,1,1,1,1,1,1,1,1,1,1,1,1
1,1,1,1,1,1,1,1,1,1,1,1,1,1,1,1,1,1,1,1
1,1,1,1,1,1,1,1,1,1,1,1,1,1,1,1,1,1,1,1
1,1,1,1,1,1,1,1,1,1,1,1,1,1,1,1,1,1,1,1
1,1,1,1,1,1,1,1,1,1,1,1,1,1,1,1,1,1,1,1
1,1,1,1,1,1,2,2,2,2,2,2,2,2,1,1,1,1,1,1
1,29,29,29,29,2,7,6,6,6,6,6,6,7,2,29,29,29,29,1
29,6,6,6,6,2,6,6,6,6,6,6,6,6,2,6,6,6,6,29
29,6,6,6,6,2,6,6,6,6,6,6,6,6,2,6,6,6,6,29
29,6,6,6,6,2,6,6,6,6,6,6,6,6,2,6,6,6,6,29
29,6,6,6,6,2,6,6,6,6,6,6,6,6,2,6,6,6,6,29
29,29,29,29,29,2,6,6,6,6,6,6,6,6,2,29,29,29,29,29
29,6,6,6,6,2,6,6,6,6,6,6,6,6,2,6,6,6,6,29
29,6,6,6,6,2,6,6,6,6,6,6,6,6,2,6,6,6,6,29
29,6,6,6,6,2,6,6,6,6,6,6,6,6,2,6,6,6,6,29
29,6,6,6,6,2,6,6,6,6,6,6,6,6,2,6,6,6,6,29
29,29,29,29,29,2,6,6,6,6,6,6,6,6,2,29,29,29,29,29
29,6,6,6,6,2,6,6,6,6,6,6,6,6,2,6,6,6,6,29
29,6,6,6,6,2,6,6,6,6,6,6,6,6,2,6,6,6,6,29
29,6,6,6,6,2,6,6,17,17,17,17,6,6,2,6,6,6,6,29
29,6,6,6,6,2,43,6,6,6,6,6,6,48,2,6,6,6,6,29
1,29,29,29,29,2,49,43,42,18,18,6,47,44,2,29,29,29,29,1
1,1,1,1,1,1,2,2,2,2,2,2,2,2,1,1,1,1,1,1
endlayer

layer
1,1,1,1,1,1,1,1,1,1,1,1,1,1,1,1,1,1,1,1
1,1,1,1,1,1,1,1,1,1,1,1,1,1,1,1,1,1,1,1
1,1,1,1,1,1,1,1,1,1,1,1,1,1,1,1,1,1,1,1
1,1,1,1,1,1,1,1,1,1,1,1,1,1,1,1,1,1,1,1
1,1,1,1,1,1,1,1,1,1,1,1,1,1,1,1,1,1,1,1
1,1,1,1,1,1,1,1,1,1,1,1,1,1,1,1,1,1,1,1
1,1,1,1,1,1,1,1,1,1,1,1,1,1,1,1,1,1,1,1
1,1,1,1,1,1,1,1,1,1,1,1,1,1,1,1,1,1,1,1
1,1,1,1,1,1,2,2,2,2,2,2,2,2,1,1,1,1,1,1
1,1,1,1,1,2,3,2,2,2,2,2,2,3,2,1,1,1,1,1
1,29,29,29,29,2,2,2,2,2,2,2,2,2,2,29,29,29,29,1
1,29,29,29,29,2,2,2,2,2,2,2,2,2,2,29,29,29,29,1
1,29,29,29,29,2,2,2,6,6,6,6,2,2,2,29,29,29,29,1
1,29,29,29,29,2,2,2,6,6,6,6,2,2,2,29,29,29,29,1
1,29,29,29,29,2,2,2,6,6,6,6,2,2,2,29,29,29,29,1
1,29,29,29,29,2,2,2,6,6,6,6,2,2,2,29,29,29,29,1
1,29,29,29,29,2,2,2,6,6,6,6,2,2,2,29,29,29,29,1
1,29,29,29,29,2,2,2,6,6,6,6,2,2,2,29,29,29,29,1
1,29,29,29,29,2,2,2,6,6,6,6,2,2,2,29,29,29,29,1
1,29,29,29,29,2,2,2,6,6,6,6,2,2,2,29,29,29,29,1
1,29,29,29,29,2,2,2,6,6,6,6,2,2,2,29,29,29,29,1
1,29,29,29,29,2,2,2,6,6,6,6,2,2,2,29,29,29,29,1
1,29,29,29,29,2,2,2,2,2,2,2,2,2,2,29,29,29,29,1
1,29,29,29,29,2,2,2,2,2,2,2,2,2,2,29,29,29,29,1
1,1,1,1,1,2,3,2,2,18,18,2,2,3,2,1,1,1,1,1
1,1,1,1,1,1,2,2,2,2,2,2,2,2,1,1,1,1,1,1
endlayer

layer
1,1,1,1,1,1,1,1,1,1,1,1,1,1,1,1,1,1,1,1
1,1,1,1,1,1,1,1,1,1,1,1,1,1,1,1,1,1,1,1
1,1,1,1,1,1,1,1,1,1,1,1,1,1,1,1,1,1,1,1
1,1,1,1,1,1,1,1,1,1,1,1,1,1,1,1,1,1,1,1
1,1,1,1,1,1,1,1,1,1,1,1,1,1,1,1,1,1,1,1
1,1,1,1,1,1,1,1,1,1,1,1,1,1,1,1,1,1,1,1
1,1,1,1,1,1,1,1,1,1,1,1,1,1,1,1,1,1,1,1
1,1,1,1,1,1,1,1,1,1,1,1,1,1,1,1,1,1,1,1
1,1,1,1,1,1,2,2,2,2,2,2,2,2,1,1,1,1,1,1
1,29,29,29,29,2,7,6,6,6,6,6,6,7,2,29,29,29,29,1
29,34,6,6,33,2,6,6,6,6,6,6,6,6,2,32,31,6,30,29
29,14,6,6,6,35,6,17,17,17,17,17,17,6,2,14,6,6,13,29
29,13,6,6,36,2,6,17,6,6,6,6,17,6,37,6,6,6,36,29
29,30,6,40,39,2,6,17,6,6,6,6,17,6,2,33,6,6,38,29
29,29,29,29,29,2,6,17,6,6,6,6,17,6,2,29,29,29,29,29
29,34,6,6,33,2,6,17,6,6,6,6,17,6,2,32,31,6,30,29
29,14,6,6,6,35,6,17,6,6,6,6,17,6,2,14,6,6,13,29
29,13,6,6,36,2,6,17,6,6,6,6,17,6,37,6,6,6,36,29
29,30,6,40,39,2,6,17,6,6,6,6,17,6,2,33,18,6,38,29
29,29,29,29,29,2,6,17,6,6,6,6,17,6,2,29,29,29,29,29
29,34,6,6,33,2,6,17,6,6,6,6,17,6,2,32,31,6,30,29
29,14,6,6,6,35,6,17,6,6,6,6,17,6,2,14,6,6,13,29
29,13,6,6,36,2,6,17,17,17,17,17,17,6,37,6,6,6,36,29
29,30,6,40,39,2,43,6,6,6,6,6,6,48,2,33,6,6,38,29
1,29,29,29,29,2,44,43,42,18,18,6,45,44,2,29,29,29,29,1
1,1,1,1,1,1,2,2,2,2,2,2,2,2,1,1,1,1,1,1
endlayer

layer
1,1,1,1,1,1,1,1,1,1,1,1,1,1,1,1,1,1,1,1
1,1,1,1,1,1,1,1,1,1,1,1,1,1,1,1,1,1,1,1
1,1,1,1,1,1,1,1,1,1,1,1,1,1,1,1,1,1,1,1
1,1,1,1,1,1,1,1,1,1,1,1,1,1,1,1,1,1,1,1
1,1,1,1,1,1,1,1,1,1,1,1,1,1,1,1,1,1,1,1
1,1,1,1,1,1,1,1,1,1,1,1,1,1,1,1,1,1,1,1
1,1,1,1,1,1,1,1,1,1,1,1,1,1,1,1,1,1,1,1
1,1,1,1,1,1,1,1,1,1,1,1,1,1,1,1,1,1,1,1
1,1,1,1,1,1,2,2,2,2,2,2,2,2,1,1,1,1,1,1
1,29,29,29,29,2,7,6,6,6,6,6,6,7,2,29,29,29,29,1
29,6,6,6,33,2,6,6,6,6,6,6,6,6,2,6,6,6,6,29
29,6,6,6,6,46,6,6,6,6,6,6,6,6,2,6,6,6,6,29
29,6,6,6,6,2,6,6,6,6,6,6,6,6,46,6,6,6,6,29
29,6,6,6,6,2,6,6,6,6,6,6,6,6,2,33,6,6,6,29
29,29,29,29,29,2,6,6,6,6,6,6,6,6,2,29,29,29,29,29
29,6,6,6,33,2,6,6,6,6,6,6,6,6,2,6,6,6,6,29
29,6,6,6,6,46,6,6,6,6,6,6,6,6,2,6,6,6,6,29
29,6,6,6,6,2,6,6,6,6,6,6,6,6,46,6,6,6,6,29
29,6,6,6,6,2,6,6,6,6,6,6,6,6,2,33,18,6,6,29
29,29,29,29,29,2,6,6,6,6,6,6,6,6,2,29,29,29,29,29
29,6,6,6,33,2,6,6,6,6,6,6,6,6,2,6,6,6,6,29
29,6,6,6,6,46,6,6,6,6,6,6,6,6,2,6,6,6,6,29
29,6,6,6,6,2,6,6,17,17,17,17,6,6,46,6,6,6,6,29
29,6,6,6,6,2,43,6,6,6,6,6,6,45,2,33,6,6,6,29
1,29,29,29,29,2,44,41,42,18,18,6,47,44,2,29,29,29,29,1
1,1,1,1,1,1,2,2,2,2,2,2,2,2,1,1,1,1,1,1
endlayer

layer
1,1,1,1,1,1,1,1,1,1,1,1,1,1,1,1,1,1,1,1
1,1,1,1,1,1,1,1,1,1,1,1,1,1,1,1,1,1,1,1
1,1,1,1,1,1,1,1,1,1,1,1,1,1,1,1,1,1,1,1
1,1,1,1,1,1,1,1,1,1,1,1,1,1,1,1,1,1,1,1
1,1,1,1,1,1,1,1,1,1,1,1,1,1,1,1,1,1,1,1
1,1,1,1,1,1,1,1,1,1,1,1,1,1,1,1,1,1,1,1
1,1,1,1,1,1,1,1,1,1,1,1,1,1,1,1,1,1,1,1
1,1,1,1,1,1,1,1,1,1,1,1,1,1,1,1,1,1,1,1
1,1,1,1,1,1,2,2,2,2,2,2,2,2,1,1,1,1,1,1
1,29,29,29,29,2,7,6,6,6,6,6,6,7,2,29,29,29,29,1
29,6,6,6,6,2,6,6,6,6,6,6,6,6,2,6,6,6,6,29
29,6,6,6,6,2,6,6,6,6,6,6,6,6,2,6,6,6,6,29
29,6,6,6,6,2,6,6,6,6,6,6,6,6,2,6,6,6,6,29
29,6,6,6,6,2,6,6,6,6,6,6,6,6,2,6,6,6,6,29
29,29,29,29,29,2,6,6,6,6,6,6,6,6,2,29,29,29,29,29
29,6,6,6,6,2,6,6,6,6,6,6,6,6,2,6,6,6,6,29
29,6,6,6,6,2,6,6,6,6,6,6,6,6,2,6,6,6,6,29
29,6,6,6,6,2,6,6,6,6,6,6,6,6,2,6,6,6,6,29
29,6,6,6,6,2,6,6,6,6,6,6,6,6,2,6,6,6,6,29
29,29,29,29,29,2,6,6,6,6,6,6,6,6,2,29,29,29,29,29
29,6,6,6,6,2,6,6,6,6,6,6,6,6,2,6,6,6,6,29
29,6,6,6,6,2,6,6,6,6,6,6,6,6,2,6,6,6,6,29
29,6,6,6,6,2,6,6,17,17,17,17,6,47,2,6,6,6,6,29
29,6,6,6,6,2,43,6,6,6,6,6,6,45,2,6,6,6,6,29
1,29,29,29,29,2,44,41,42,18,18,6,47,44,2,29,29,29,29,1
1,1,1,1,1,1,2,2,2,2,2,2,2,2,1,1,1,1,1,1
endlayer

layer
1,1,1,1,1,1,1,1,1,1,1,1,1,1,1,1,1,1,1,1
1,1,1,1,1,1,1,1,1,1,1,1,1,1,1,1,1,1,1,1
1,1,1,1,1,1,1,1,1,1,1,1,1,1,1,1,1,1,1,1
1,1,1,1,1,1,1,1,1,1,1,1,1,1,1,1,1,1,1,1
1,1,1,1,1,1,1,1,1,1,1,1,1,1,1,1,1,1,1,1
1,1,1,1,1,1,1,1,1,2,2,1,1,1,1,1,1,1,1,1
1,1,1,1,1,1,1,1,1,2,2,1,1,1,1,1,1,1,1,1
1,1,1,1,1,1,1,1,1,2,2,1,1,1,1,1,1,1,1,1
1,1,1,1,1,1,2,2,2,2,2,2,2,2,1,1,1,1,1,1
1,1,1,1,1,2,3,2,2,2,2,2,2,3,2,1,1,1,1,1
1,29,29,29,29,2,2,2,2,2,2,2,2,2,2,29,29,29,29,1
1,29,29,29,29,2,2,2,2,2,2,2,2,2,2,29,29,29,29,1
1,29,29,29,29,2,2,2,6,6,6,6,2,2,2,29,29,29,29,1
1,29,29,29,29,2,2,2,6,6,6,6,2,2,2,29,29,29,29,1
1,29,29,29,29,2,2,2,6,6,6,6,2,2,2,29,29,29,29,1
1,29,29,29,29,2,2,2,6,6,6,6,2,2,2,29,29,29,29,1
1,29,29,29,29,2,2,2,6,6,6,6,2,2,2,29,29,29,29,1
1,29,29,29,29,2,2,2,6,6,6,6,2,2,2,29,29,29,29,1
1,29,29,29,29,2,2,2,6,6,6,6,2,2,2,29,29,29,29,1
1,29,29,29,29,2,2,2,6,6,6,6,2,2,2,29,29,29,29,1
1,29,29,29,29,2,2,2,6,6,6,6,2,2,2,29,29,29,29,1
1,29,29,29,29,2,2,2,6,6,6,6,2,2,2,29,29,29,29,1
1,29,29,29,29,2,2,2,2,2,2,2,2,2,2,29,29,29,29,1
1,29,29,29,29,2,2,2,2,2,2,2,2,2,2,29,29,29,29,1
1,1,1,1,1,2,3,2,2,18,18,2,2,3,2,1,1,1,1,1
1,1,1,1,1,1,2,2,2,2,2,2,2,2,1,1,1,1,1,1
endlayer

layer
1,1,1,1,1,1,1,1,1,1,1,1,1,1,1,1,1,1,1,1
1,1,1,1,1,1,1,1,1,1,1,1,1,1,1,1,1,1,1,1
1,1,1,1,1,1,1,1,1,1,1,1,1,1,1,1,1,1,1,1
1,1,1,1,1,1,1,1,1,1,1,1,1,1,1,1,1,1,1,1
1,1,1,1,1,1,1,1,2,15,15,2,1,1,1,1,1,1,1,1
1,1,1,1,1,1,1,1,2,6,6,2,1,1,1,1,1,1,1,1
1,1,1,1,1,1,1,1,2,6,6,2,1,1,1,1,1,1,1,1
1,1,1,1,1,1,1,1,2,6,6,2,1,1,1,1,1,1,1,1
1,1,1,1,1,1,2,2,2,6,6,2,2,2,1,1,1,1,1,1
1,29,29,29,29,2,7,6,6,6,6,6,6,7,2,29,29,29,29,1
29,34,6,6,33,2,6,6,6,6,6,6,6,6,2,32,31,6,30,29
29,14,6,6,6,35,6,17,17,17,17,17,17,6,2,14,6,6,13,29
29,13,6,6,36,2,6,17,6,6,6,6,17,6,37,6,6,6,36,29
29,30,6,40,39,2,6,17,6,6,6,6,17,6,2,33,6,6,38,29
29,29,29,29,29,2,6,17,6,6,6,6,17,6,2,29,29,29,29,29
29,34,6,6,33,2,6,17,6,6,6,6,17,6,2,32,31,6,30,29
29,14,6,6,6,35,6,17,6,6,6,6,17,6,2,14,6,6,13,29
29,13,6,6,36,2,6,17,6,6,6,6,17,6,37,6,6,6,36,29
29,30,6,40,39,2,6,17,6,6,6,6,17,6,2,33,6,6,38,29
29,29,29,29,29,2,6,17,6,6,6,6,17,6,2,29,29,29,29,29
29,34,6,6,33,2,6,17,6,6,6,6,17,6,2,32,31,6,30,29
29,14,6,6,6,35,6,17,6,6,6,6,17,6,2,14,6,6,13,29
29,13,6,6,36,2,41,17,17,17,17,17,17,6,37,6,6,6,36,29
29,30,6,40,39,2,43,6,6,6,6,6,6,50,2,33,6,6,38,29
1,29,29,29,29,2,49,43,42,18,18,6,45,49,2,29,29,29,29,1
1,1,1,1,1,1,2,2,2,2,2,2,2,2,1,1,1,1,1,1
endlayer

layer
1,1,1,1,1,1,1,1,1,1,1,1,1,1,1,1,1,1,1,1
1,1,1,1,1,1,1,1,1,1,1,1,1,1,1,1,1,1,1,1
1,1,1,1,1,1,1,1,1,51,51,1,1,1,1,1,1,1,1,1
1,1,1,1,1,1,1,1,51,15,15,2,1,1,1,1,1,1,1,1
1,1,1,1,1,1,1,1,2,6,6,2,1,1,1,1,1,1,1,1
1,1,1,1,1,1,1,1,3,6,6,3,1,1,1,1,1,1,1,1
1,1,1,1,1,1,1,1,2,6,6,2,1,1,1,1,1,1,1,1
1,1,1,1,1,1,1,1,2,6,6,2,1,1,1,1,1,1,1,1
1,1,1,1,1,1,2,2,2,6,6,2,2,2,1,1,1,1,1,1
1,29,29,29,29,2,7,6,6,6,6,6,6,7,2,29,29,29,29,1
29,6,6,6,33,2,6,6,6,6,6,6,6,6,2,6,6,6,6,29
29,6,6,6,6,46,6,6,6,6,6,6,6,6,2,6,6,6,6,29
29,6,6,6,6,2,6,6,6,6,6,6,6,6,46,6,6,6,6,29
29,6,6,6,6,2,6,6,6,6,6,6,6,6,2,33,6,6,6,29
29,29,29,29,29,2,6,6,6,6,6,6,6,6,2,29,29,29,29,29
29,6,6,6,33,2,6,6,6,6,6,6,6,6,2,6,6,6,6,29
29,6,6,6,6,46,6,6,6,6,6,6,6,6,2,6,6,6,6,29
29,6,6,6,6,2,6,6,6,6,6,6,6,6,46,6,6,6,6,29
29,6,6,6,6,2,6,6,6,6,6,6,6,6,2,33,6,6,6,29
29,29,29,29,29,2,6,6,6,6,6,6,6,6,2,29,29,29,29,29
29,6,6,6,33,2,6,6,6,6,6,6,6,6,2,6,6,6,6,29
29,6,6,6,6,46,6,6,6,6,6,6,6,6,2,6,6,6,6,29
29,6,6,6,6,2,41,6,6,6,6,6,6,6,46,6,6,6,6,29
29,6,6,6,6,2,43,6,6,6,6,6,6,42,2,33,6,6,6,29
1,29,29,29,29,2,44,41,42,18,18,6,45,44,2,29,29,29,29,1
1,1,1,1,1,1,2,2,2,2,2,2,2,2,1,1,1,1,1,1
endlayer

layer
1,1,1,1,1,1,1,1,1,1,1,1,1,1,1,1,1,1,1,1
1,1,1,1,1,1,1,1,1,51,51,1,1,1,1,1,1,1,1,1
1,1,1,1,1,1,1,1,1,15,15,1,1,1,1,1,1,1,1,1
1,1,1,1,1,1,1,1,51,6,1,51,1,1,1,1,1,1,1,1
1,1,1,1,1,1,1,1,51,6,1,2,1,1,1,1,1,1,1,1
1,1,1,1,1,1,1,1,2,6,6,2,1,1,1,1,1,1,1,1
1,1,1,1,1,1,1,1,2,6,6,2,1,1,1,1,1,1,1,1
1,1,1,1,1,1,1,1,2,6,6,2,1,1,1,1,1,1,1,1
1,1,1,1,1,1,2,2,2,6,6,2,2,2,1,1,1,1,1,1
1,29,29,29,29,2,7,6,6,6,6,6,6,7,2,29,29,29,29,1
29,6,6,6,6,2,6,6,6,6,6,6,6,6,2,6,6,6,6,29
29,6,6,6,6,2,6,6,6,6,6,6,6,6,2,6,6,6,6,29
29,6,6,6,6,2,6,6,6,6,6,6,6,6,2,6,6,6,6,29
29,6,6,6,6,2,6,6,6,6,6,6,6,6,2,6,6,6,6,29
29,29,29,29,29,2,6,6,6,6,6,6,6,6,2,29,29,29,29,29
29,6,6,6,6,2,6,6,6,6,6,6,6,6,2,6,6,6,6,29
29,6,6,6,6,2,6,6,6,6,6,6,6,6,2,6,6,6,6,29
29,6,6,6,6,2,6,6,6,6,6,6,6,6,2,6,6,6,6,29
29,6,6,6,6,2,6,6,6,6,6,6,6,6,2,52,6,6,6,29
29,29,29,29,29,2,6,6,6,6,6,6,6,6,2,29,29,29,29,29
29,6,6,6,6,2,6,6,6,6,6,6,6,6,2,6,6,6,6,29
29,6,6,6,6,2,6,6,6,6,6,6,6,6,2,6,6,6,6,29
29,6,6,6,6,2,41,6,6,6,6,6,6,6,2,6,6,6,6,29
29,6,6,6,6,2,43,6,6,6,6,6,6,42,2,6,6,6,6,29
1,29,29,29,29,2,44,41,6,6,6,42,45,44,2,29,29,29,29,1
1,1,1,1,1,1,2,2,2,2,2,2,2,2,1,1,1,1,1,1
endlayer

layer
1,1,1,1,1,1,1,1,1,51,51,1,1,1,1,1,1,1,1,1
1,1,1,1,1,1,1,1,51,15,15,51,1,1,1,1,1,1,1,1
1,1,1,1,1,1,1,1,51,1,1,51,1,1,1,1,1,1,1,1
1,1,1,1,1,1,1,1,51,1,1,51,1,1,1,1,1,1,1,1
1,1,1,1,1,1,1,1,51,1,6,51,1,1,1,1,1,1,1,1
1,1,1,1,1,1,1,1,51,51,51,51,1,1,1,1,1,1,1,1
1,1,1,1,1,1,1,1,1,2,2,1,1,1,1,1,1,1,1,1
1,1,1,1,1,1,1,1,1,2,2,1,1,1,1,1,1,1,1,1
1,1,1,1,1,1,2,2,2,22,22,2,2,2,1,1,1,1,1,1
1,1,1,1,1,2,3,27,6,6,6,6,26,3,2,1,1,1,1,1
1,29,29,29,29,2,28,6,6,6,6,6,6,28,2,29,29,29,29,1
1,29,29,29,29,2,6,6,6,6,6,6,6,6,2,29,29,29,29,1
1,29,29,29,29,2,6,6,6,6,6,6,6,6,2,29,29,29,29,1
1,29,29,29,29,2,6,6,6,6,6,6,6,6,2,29,29,29,29,1
1,29,29,29,29,2,6,6,6,6,6,6,6,6,2,29,29,29,29,1
1,29,29,29,29,2,6,6,6,6,6,6,6,6,2,29,29,29,29,1
1,29,29,29,29,2,6,6,6,6,6,6,6,6,2,29,29,29,29,1
1,29,29,29,29,2,6,6,6,6,6,6,6,6,2,29,29,29,29,1
1,29,29,29,29,2,6,6,6,6,6,6,6,6,2,29,29,29,29,1
1,29,29,29,29,2,6,6,6,6,6,6,6,6,2,29,29,29,29,1
1,29,29,29,29,2,6,6,6,6,6,6,6,6,2,29,29,29,29,1
1,29,29,29,29,2,6,6,6,6,6,6,6,6,2,29,29,29,29,1
1,29,29,29,29,2,41,6,6,6,6,6,6,6,2,29,29,29,29,1
1,29,29,29,29,2,43,6,6,6,6,6,6,42,2,29,29,29,29,1
1,1,1,1,1,2,49,41,6,6,6,42,45,49,2,1,1,1,1,1
1,1,1,1,1,1,2,2,2,2,2,2,2,2,1,1,1,1,1,1
endlayer

layer
1,1,1,1,1,1,1,1,51,15,51,51,1,1,1,1,1,1,1,1
1,1,1,1,1,1,1,1,51,1,1,51,1,1,1,1,1,1,1,1
1,1,1,1,1,1,1,1,1,1,1,1,1,1,1,1,1,1,1,1
1,1,1,1,1,1,1,1,51,6,1,51,1,1,1,1,1,1,1,1
1,1,1,1,1,1,1,1,51,51,51,51,1,1,1,1,1,1,1,1
1,1,1,1,1,1,1,1,1,1,1,1,1,1,1,1,1,1,1,1
1,1,1,1,1,1,1,1,1,1,1,1,1,1,1,1,1,1,1,1
1,1,1,1,1,1,1,1,1,1,1,1,1,1,1,1,1,1,1,1
1,1,1,1,1,1,1,1,1,2,2,1,1,1,1,1,1,1,1,1
1,1,1,1,1,1,1,2,2,2,2,2,2,1,1,1,1,1,1,1
1,1,1,1,1,1,2,2,2,2,2,2,2,2,1,1,1,1,1,1
1,1,1,1,1,1,2,2,2,2,2,2,2,2,1,1,1,1,1,1
1,1,1,1,1,1,2,2,2,2,2,2,2,2,1,1,1,1,1,1
1,1,1,1,1,1,2,2,2,2,2,2,2,2,1,1,1,1,1,1
1,1,1,1,1,1,2,2,2,2,2,2,2,2,1,1,1,1,1,1
1,1,1,1,1,1,2,2,2,2,2,2,2,2,1,1,1,1,1,1
1,1,1,1,1,1,2,2,2,2,2,2,2,2,1,1,1,1,1,1
1,1,1,1,1,1,2,2,2,2,2,2,2,2,1,1,1,1,1,1
1,1,1,1,1,1,2,2,2,2,2,2,2,2,1,1,1,1,1,1
1,1,1,1,1,1,2,2,2,2,2,2,2,2,1,1,1,1,1,1
1,1,1,1,1,1,2,2,2,2,2,2,2,2,1,1,1,1,1,1
1,1,1,1,1,1,2,2,2,2,2,2,2,2,1,1,1,1,1,1
1,1,1,1,1,1,2,2,2,2,2,2,2,2,1,1,1,1,1,1
1,1,1,1,1,1,2,2,2,2,2,2,2,2,1,1,1,1,1,1
1,1,1,1,1,1,2,2,2,2,2,2,2,2,1,1,1,1,1,1
1,1,1,1,1,1,1,1,1,1,1,1,1,1,1,1,1,1,1,1
endlayer

layer
1,1,1,1,1,1,1,1,51,1,1,51,1,1,1,1,1,1,1,1
1,1,1,1,1,1,1,1,51,1,1,51,1,1,1,1,1,1,1,1
1,1,1,1,1,1,1,1,51,1,1,51,1,1,1,1,1,1,1,1
1,1,1,1,1,1,1,1,51,51,51,51,1,1,1,1,1,1,1,1
1,1,1,1,1,1,1,1,1,1,1,1,1,1,1,1,1,1,1,1
1,1,1,1,1,1,1,1,1,1,1,1,1,1,1,1,1,1,1,1
1,1,1,1,1,1,1,1,1,1,1,1,1,1,1,1,1,1,1,1
1,1,1,1,1,1,1,1,1,1,1,1,1,1,1,1,1,1,1,1
1,1,1,1,1,1,1,1,1,1,1,1,1,1,1,1,1,1,1,1
1,1,1,1,1,1,1,1,1,1,1,1,1,1,1,1,1,1,1,1
1,1,1,1,1,1,1,1,1,1,1,1,1,1,1,1,1,1,1,1
1,1,1,1,1,1,1,1,1,1,1,1,1,1,1,1,1,1,1,1
1,1,1,1,1,1,1,1,1,1,1,1,1,1,1,1,1,1,1,1
1,1,1,1,1,1,1,1,1,1,1,1,1,1,1,1,1,1,1,1
1,1,1,1,1,1,1,1,1,1,1,1,1,1,1,1,1,1,1,1
1,1,1,1,1,1,1,1,1,1,1,1,1,1,1,1,1,1,1,1
1,1,1,1,1,1,1,1,1,1,1,1,1,1,1,1,1,1,1,1
1,1,1,1,1,1,1,1,1,1,1,1,1,1,1,1,1,1,1,1
1,1,1,1,1,1,1,1,1,1,1,1,1,1,1,1,1,1,1,1
1,1,1,1,1,1,1,1,1,1,1,1,1,1,1,1,1,1,1,1
1,1,1,1,1,1,1,1,1,1,1,1,1,1,1,1,1,1,1,1
1,1,1,1,1,1,1,1,1,1,1,1,1,1,1,1,1,1,1,1
1,1,1,1,1,1,1,1,1,1,1,1,1,1,1,1,1,1,1,1
1,1,1,1,1,1,1,1,1,1,1,1,1,1,1,1,1,1,1,1
1,1,1,1,1,1,1,1,1,1,1,1,1,1,1,1,1,1,1,1
1,1,1,1,1,1,1,1,1,1,1,1,1,1,1,1,1,1,1,1
endlayer

layer
1,1,1,1,1,1,1,1,51,1,1,51,1,1,1,1,1,1,1,1
1,1,1,1,1,1,1,1,51,1,1,51,1,1,1,1,1,1,1,1
1,1,1,1,1,1,1,1,51,51,25,51,1,1,1,1,1,1,1,1
1,1,1,1,1,1,1,1,1,1,1,1,1,1,1,1,1,1,1,1
1,1,1,1,1,1,1,1,1,1,1,1,1,1,1,1,1,1,1,1
1,1,1,1,1,1,1,1,1,1,1,1,1,1,1,1,1,1,1,1
1,1,1,1,1,1,1,1,1,1,1,1,1,1,1,1,1,1,1,1
1,1,1,1,1,1,1,1,1,1,1,1,1,1,1,1,1,1,1,1
1,1,1,1,1,1,1,1,1,1,1,1,1,1,1,1,1,1,1,1
1,1,1,1,1,1,1,1,1,1,1,1,1,1,1,1,1,1,1,1
1,1,1,1,1,1,1,1,1,1,1,1,1,1,1,1,1,1,1,1
1,1,1,1,1,1,1,1,1,1,1,1,1,1,1,1,1,1,1,1
1,1,1,1,1,1,1,1,1,1,1,1,1,1,1,1,1,1,1,1
1,1,1,1,1,1,1,1,1,1,1,1,1,1,1,1,1,1,1,1
1,1,1,1,1,1,1,1,1,1,1,1,1,1,1,1,1,1,1,1
1,1,1,1,1,1,1,1,1,1,1,1,1,1,1,1,1,1,1,1
1,1,1,1,1,1,1,1,1,1,1,1,1,1,1,1,1,1,1,1
1,1,1,1,1,1,1,1,1,1,1,1,1,1,1,1,1,1,1,1
1,1,1,1,1,1,1,1,1,1,1,1,1,1,1,1,1,1,1,1
1,1,1,1,1,1,1,1,1,1,1,1,1,1,1,1,1,1,1,1
1,1,1,1,1,1,1,1,1,1,1,1,1,1,1,1,1,1,1,1
1,1,1,1,1,1,1,1,1,1,1,1,1,1,1,1,1,1,1,1
1,1,1,1,1,1,1,1,1,1,1,1,1,1,1,1,1,1,1,1
1,1,1,1,1,1,1,1,1,1,1,1,1,1,1,1,1,1,1,1
1,1,1,1,1,1,1,1,1,1,1,1,1,1,1,1,1,1,1,1
1,1,1,1,1,1,1,1,1,1,1,1,1,1,1,1,1,1,1,1
endlayer

layer
1,1,1,1,1,1,1,1,51,1,1,1,1,1,1,1,1,1,1,1
1,1,1,1,1,1,1,1,1,1,1,51,1,1,1,1,1,1,1,1
1,1,1,1,1,1,1,1,51,1,1,51,1,1,1,1,1,1,1,1
1,1,1,1,1,1,1,1,1,1,1,1,1,1,1,1,1,1,1,1
1,1,1,1,1,1,1,1,1,1,1,1,1,1,1,1,1,1,1,1
1,1,1,1,1,1,1,1,1,1,1,1,1,1,1,1,1,1,1,1
1,1,1,1,1,1,1,1,1,1,1,1,1,1,1,1,1,1,1,1
1,1,1,1,1,1,1,1,1,1,1,1,1,1,1,1,1,1,1,1
1,1,1,1,1,1,1,1,1,1,1,1,1,1,1,1,1,1,1,1
1,1,1,1,1,1,1,1,1,1,1,1,1,1,1,1,1,1,1,1
1,1,1,1,1,1,1,1,1,1,1,1,1,1,1,1,1,1,1,1
1,1,1,1,1,1,1,1,1,1,1,1,1,1,1,1,1,1,1,1
1,1,1,1,1,1,1,1,1,1,1,1,1,1,1,1,1,1,1,1
1,1,1,1,1,1,1,1,1,1,1,1,1,1,1,1,1,1,1,1
1,1,1,1,1,1,1,1,1,1,1,1,1,1,1,1,1,1,1,1
1,1,1,1,1,1,1,1,1,1,1,1,1,1,1,1,1,1,1,1
1,1,1,1,1,1,1,1,1,1,1,1,1,1,1,1,1,1,1,1
1,1,1,1,1,1,1,1,1,1,1,1,1,1,1,1,1,1,1,1
1,1,1,1,1,1,1,1,1,1,1,1,1,1,1,1,1,1,1,1
1,1,1,1,1,1,1,1,1,1,1,1,1,1,1,1,1,1,1,1
1,1,1,1,1,1,1,1,1,1,1,1,1,1,1,1,1,1,1,1
1,1,1,1,1,1,1,1,1,1,1,1,1,1,1,1,1,1,1,1
1,1,1,1,1,1,1,1,1,1,1,1,1,1,1,1,1,1,1,1
1,1,1,1,1,1,1,1,1,1,1,1,1,1,1,1,1,1,1,1
1,1,1,1,1,1,1,1,1,1,1,1,1,1,1,1,1,1,1,1
1,1,1,1,1,1,1,1,1,1,1,1,1,1,1,1,1,1,1,1
endlayer

layer
1,1,1,1,1,1,1,1,1,1,1,1,1,1,1,1,1,1,1,1
1,1,1,1,1,1,1,1,1,1,1,1,1,1,1,1,1,1,1,1
1,1,1,1,1,1,1,1,1,1,1,1,1,1,1,1,1,1,1,1
1,1,1,1,1,1,1,1,1,1,1,1,1,1,1,1,1,1,1,1
1,1,1,1,1,1,1,1,1,1,1,1,1,1,1,1,1,1,1,1
1,1,1,1,1,1,1,1,1,1,1,1,1,1,1,1,1,1,1,1
1,1,1,1,1,1,1,1,1,1,1,1,1,1,1,1,1,1,1,1
1,1,1,1,1,1,1,1,1,1,1,1,1,1,1,1,1,1,1,1
1,1,1,1,1,1,1,1,1,1,1,1,1,1,1,1,1,1,1,1
1,1,1,1,1,1,1,1,1,1,1,1,1,1,1,1,1,1,1,1
1,1,1,1,1,1,1,1,1,1,1,1,1,1,1,1,1,1,1,1
1,1,1,1,1,1,1,1,1,1,1,1,1,1,1,1,1,1,1,1
1,1,1,1,1,1,1,1,1,1,1,1,1,1,1,1,1,1,1,1
1,1,1,1,1,1,1,1,1,1,1,1,1,1,1,1,1,1,1,1
1,1,1,1,1,1,1,1,1,1,1,1,1,1,1,1,1,1,1,1
1,1,1,1,1,1,1,1,1,1,1,1,1,1,1,1,1,1,1,1
1,1,1,1,1,1,1,1,1,1,1,1,1,1,1,1,1,1,1,1
1,1,1,1,1,1,1,1,1,1,1,1,1,1,1,1,1,1,1,1
1,1,1,1,1,1,1,1,1,1,1,1,1,1,1,1,1,1,1,1
1,1,1,1,1,1,1,1,1,1,1,1,1,1,1,1,1,1,1,1
1,1,1,1,1,1,1,1,1,1,1,1,1,1,1,1,1,1,1,1
1,1,1,1,1,1,1,1,1,1,1,1,1,1,1,1,1,1,1,1
1,1,1,1,1,1,1,1,1,1,1,1,1,1,1,1,1,1,1,1
1,1,1,1,1,1,1,1,1,1,1,1,1,1,1,1,1,1,1,1
1,1,1,1,1,1,1,1,1,1,1,1,1,1,1,1,1,1,1,1
1,1,1,1,1,1,1,1,1,1,1,1,1,1,1,1,1,1,1,1
endlayer

layer
1,1,1,1,1,1,1,1,1,1,1,1,1,1,1,1,1,1,1,1
1,1,1,1,1,1,1,1,1,1,1,1,1,1,1,1,1,1,1,1
1,1,1,1,1,1,1,1,1,1,1,1,1,1,1,1,1,1,1,1
1,1,1,1,1,1,1,1,1,1,1,1,1,1,1,1,1,1,1,1
1,1,1,1,1,1,1,1,1,1,1,1,1,1,1,1,1,1,1,1
1,1,1,1,1,1,1,1,1,1,1,1,1,1,1,1,1,1,1,1
1,1,1,1,1,1,1,1,1,1,1,1,1,1,1,1,1,1,1,1
1,1,1,1,1,1,1,1,1,1,1,1,1,1,1,1,1,1,1,1
1,1,1,1,1,1,1,1,1,1,1,1,1,1,1,1,1,1,1,1
1,1,1,1,1,1,1,1,1,1,1,1,1,1,1,1,1,1,1,1
1,1,1,1,1,1,1,1,1,1,1,1,1,1,1,1,1,1,1,1
1,1,1,1,1,1,1,1,1,1,1,1,1,1,1,1,1,1,1,1
1,1,1,1,1,1,1,1,1,1,1,1,1,1,1,1,1,1,1,1
1,1,1,1,1,1,1,1,1,1,1,1,1,1,1,1,1,1,1,1
1,1,1,1,1,1,1,1,1,1,1,1,1,1,1,1,1,1,1,1
1,1,1,1,1,1,1,1,1,1,1,1,1,1,1,1,1,1,1,1
1,1,1,1,1,1,1,1,1,1,1,1,1,1,1,1,1,1,1,1
1,1,1,1,1,1,1,1,1,1,1,1,1,1,1,1,1,1,1,1
1,1,1,1,1,1,1,1,1,1,1,1,1,1,1,1,1,1,1,1
1,1,1,1,1,1,1,1,1,1,1,1,1,1,1,1,1,1,1,1
1,1,1,1,1,1,1,1,1,1,1,1,1,1,1,1,1,1,1,1
1,1,1,1,1,1,1,1,1,1,1,1,1,1,1,1,1,1,1,1
1,1,1,1,1,1,1,1,1,1,1,1,1,1,1,1,1,1,1,1
1,1,1,1,1,1,1,1,1,1,1,1,1,1,1,1,1,1,1,1
1,1,1,1,1,1,1,1,1,1,1,1,1,1,1,1,1,1,1,1
1,1,1,1,1,1,1,1,1,1,1,1,1,1,1,1,1,1,1,1
endlayer

layer
1,1,1,1,1,1,1,1,1,1,1,1,1,1,1,1,1,1,1,1
1,1,1,1,1,1,1,1,1,1,1,1,1,1,1,1,1,1,1,1
1,1,1,1,1,1,1,1,1,1,1,1,1,1,1,1,1,1,1,1
1,1,1,1,1,1,1,1,1,1,1,1,1,1,1,1,1,1,1,1
1,1,1,1,1,1,1,1,1,1,1,1,1,1,1,1,1,1,1,1
1,1,1,1,1,1,1,1,1,1,1,1,1,1,1,1,1,1,1,1
1,1,1,1,1,1,1,1,1,1,1,1,1,1,1,1,1,1,1,1
1,1,1,1,1,1,1,1,1,1,1,1,1,1,1,1,1,1,1,1
1,1,1,1,1,1,1,1,1,1,1,1,1,1,1,1,1,1,1,1
1,1,1,1,1,1,1,1,1,1,1,1,1,1,1,1,1,1,1,1
1,1,1,1,1,1,1,1,1,1,1,1,1,1,1,1,1,1,1,1
1,1,1,1,1,1,1,1,1,1,1,1,1,1,1,1,1,1,1,1
1,1,1,1,1,1,1,1,1,1,1,1,1,1,1,1,1,1,1,1
1,1,1,1,1,1,1,1,1,1,1,1,1,1,1,1,1,1,1,1
1,1,1,1,1,1,1,1,1,1,1,1,1,1,1,1,1,1,1,1
1,1,1,1,1,1,1,1,1,1,1,1,1,1,1,1,1,1,1,1
1,1,1,1,1,1,1,1,1,1,1,1,1,1,1,1,1,1,1,1
1,1,1,1,1,1,1,1,1,1,1,1,1,1,1,1,1,1,1,1
1,1,1,1,1,1,1,1,1,1,1,1,1,1,1,1,1,1,1,1
1,1,1,1,1,1,1,1,1,1,1,1,1,1,1,1,1,1,1,1
1,1,1,1,1,1,1,1,1,1,1,1,1,1,1,1,1,1,1,1
1,1,1,1,1,1,1,1,1,1,1,1,1,1,1,1,1,1,1,1
1,1,1,1,1,1,1,1,1,1,1,1,1,1,1,1,1,1,1,1
1,1,1,1,1,1,1,1,1,1,1,1,1,1,1,1,1,1,1,1
1,1,1,1,1,1,1,1,1,1,1,1,1,1,1,1,1,1,1,1
1,1,1,1,1,1,1,1,1,1,1,1,1,1,1,1,1,1,1,1
endlayer

layer
1,1,1,1,1,1,1,1,51,51,51,51,1,1,1,1,1,1,1,1
1,1,1,1,1,1,1,51,51,1,1,51,51,1,1,1,1,1,1,1
1,1,1,1,1,1,1,51,51,1,1,51,51,1,1,1,1,1,1,1
1,1,1,1,1,1,1,1,51,51,51,51,1,1,1,1,1,1,1,1
1,1,1,1,1,1,1,1,1,1,1,1,1,1,1,1,1,1,1,1
1,1,1,1,1,1,1,1,1,1,1,1,1,1,1,1,1,1,1,1
1,1,1,1,1,1,1,1,1,1,1,1,1,1,1,1,1,1,1,1
1,1,1,1,1,1,1,1,1,1,1,1,1,1,1,1,1,1,1,1
1,1,1,1,1,1,1,1,1,1,1,1,1,1,1,1,1,1,1,1
1,1,1,1,1,1,1,1,1,1,1,1,1,1,1,1,1,1,1,1
1,1,1,1,1,1,1,1,1,1,1,1,1,1,1,1,1,1,1,1
1,1,1,1,1,1,1,1,1,1,1,1,1,1,1,1,1,1,1,1
1,1,1,1,1,1,1,1,1,1,1,1,1,1,1,1,1,1,1,1
1,1,1,1,1,1,1,1,1,1,1,1,1,1,1,1,1,1,1,1
1,1,1,1,1,1,1,1,1,1,1,1,1,1,1,1,1,1,1,1
1,1,1,1,1,1,1,1,1,1,1,1,1,1,1,1,1,1,1,1
1,1,1,1,1,1,1,1,1,1,1,1,1,1,1,1,1,1,1,1
1,1,1,1,1,1,1,1,1,1,1,1,1,1,1,1,1,1,1,1
1,1,1,1,1,1,1,1,1,1,1,1,1,1,1,1,1,1,1,1
1,1,1,1,1,1,1,1,1,1,1,1,1,1,1,1,1,1,1,1
1,1,1,1,1,1,1,1,1,1,1,1,1,1,1,1,1,1,1,1
1,1,1,1,1,1,1,1,1,1,1,1,1,1,1,1,1,1,1,1
1,1,1,1,1,1,1,1,1,1,1,1,1,1,1,1,1,1,1,1
1,1,1,1,1,1,1,1,1,1,1,1,1,1,1,1,1,1,1,1
1,1,1,1,1,1,1,1,1,1,1,1,1,1,1,1,1,1,1,1
1,1,1,1,1,1,1,1,1,1,1,1,1,1,1,1,1,1,1,1
endlayer

